{"blocks":[{"x":-3,"y":8,"z":1,"id":"overworld:leaves"},{"x":-3,"y":9,"z":1,"id":"overworld:leaves"},{"x":-2,"y":9,"z":1,"id":"overworld:leaves"},{"x":-1,"y":9,"z":0,"id":"overworld:leaves"},{"x":-1,"y":9,"z":1,"id":"overworld:log{down=false,left=true,right=true,back=true,size=5,up=true,front=true}"},{"x":-1,"y":9,"z":2,"id":"overworld:leaves"},{"x":-1,"y":10,"z":1,"id":"overworld:leaves"},{"x":0,"y":0,"z":0,"id":"overworld:log{down=false,left=false,right=false,back=false,size=7,up=true,front=false}"},{"x":0,"y":1,"z":0,"id":"overworld:log{down=true,left=false,right=false,back=false,size=7,up=true,front=false}"},{"x":0,"y":2,"z":0,"id":"overworld:log{down=true,left=false,right=false,back=false,size=6,up=true,front=false}"},{"x":0,"y":3,"z":0,"id":"overworld:log{down=true,left=false,right=false,back=false,size=6,up=true,front=false}"},{"x":0,"y":4,"z":0,"id":"overworld:log{down=true,left=false,right=false,back=false,size=6,up=true,front=false}"},{"x":0,"y":5,"z":0,"id":"overworld:log{down=true,left=false,right=false,back=true,size=6,up=false,front=false}"},{"x":0,"y":5,"z":1,"id":"overworld:log{down=false,left=false,right=false,back=false,size=6,up=true,front=true}"},{"x":0,"y":6,"z":1,"id":"overworld:log{down=true,left=false,right=false,back=false,size=6,up=true,front=false}"},{"x":0,"y":7,"z":1,"id":"overworld:log{down=true,left=false,right=false,back=false,size=6,up=true,front=false}"},{"x":0,"y":8,"z":-2,"id":"overworld:leaves"},{"x":0,"y":8,"z":1,"id":"overworld:log{down=true,left=false,right=false,back=false,size=5,up=true,front=false}"},{"x":0,"y":8,"z":4,"id":"overworld:leaves"},{"x":0,"y":9,"z":-2,"id":"overworld:leaves"},{"x":0,"y":9,"z":-1,"id":"overworld:leaves"},{"x":0,"y":9,"z":0,"id":"overworld:log{down=false,left=true,right=true,back=true,size=5,up=true,front=true}"},{"x":0,"y":9,"z":1,"id":"overworld:log{down=true,left=true,right=true,back=true,size=5,up=true,front=true}"},{"x":0,"y":9,"z":2,"id":"overworld:log{down=false,left=true,right=true,back=true,size=5,up=true,front=true}"},{"x":0,"y":9,"z":3,"id":"overworld:leaves"},{"x":0,"y":9,"z":4,"id":"overworld:leaves"},{"x":0,"y":10,"z":0,"id":"overworld:leaves"},{"x":0,"y":10,"z":1,"id":"overworld:leaves"},{"x":0,"y":10,"z":2,"id":"overworld:leaves"},{"x":1,"y":9,"z":0,"id":"overworld:leaves"},{"x":1,"y":9,"z":1,"id":"overworld:log{down=false,left=true,right=true,back=true,size=4,up=true,front=true}"},{"x":1,"y":9,"z":2,"id":"overworld:leaves"},{"x":1,"y":10,"z":1,"id":"overworld:leaves"},{"x":2,"y":9,"z":1,"id":"overworld:leaves"},{"x":3,"y":8,"z":1,"id":"overworld:leaves"},{"x":3,"y":9,"z":1,"id":"overworld:leaves"}]}