{"blocks":[{"x":-4,"y":6,"z":-1,"id":"overworld:leaves"},{"x":-4,"y":6,"z":0,"id":"overworld:leaves"},{"x":-4,"y":6,"z":1,"id":"overworld:leaves"},{"x":-3,"y":3,"z":0,"id":"overworld:log{left=false,front=false,right=true,down=false,size=3,back=false,up=true}"},{"x":-3,"y":4,"z":0,"id":"overworld:log{left=false,front=false,right=false,down=true,size=2,back=false,up=true}"},{"x":-3,"y":5,"z":0,"id":"overworld:log{left=false,front=false,right=true,down=true,size=2,back=false,up=true}"},{"x":-3,"y":6,"z":-2,"id":"overworld:leaves"},{"x":-3,"y":6,"z":-1,"id":"overworld:leaves"},{"x":-3,"y":6,"z":0,"id":"overworld:leaves"},{"x":-3,"y":6,"z":1,"id":"overworld:leaves"},{"x":-3,"y":6,"z":2,"id":"overworld:leaves"},{"x":-2,"y":3,"z":0,"id":"overworld:log{left=true,front=false,right=true,down=false,size=3,back=false,up=false}"},{"x":-2,"y":4,"z":2,"id":"overworld:log{left=false,front=false,right=true,down=false,size=2,back=false,up=true}"},{"x":-2,"y":5,"z":-2,"id":"overworld:leaves"},{"x":-2,"y":5,"z":-1,"id":"overworld:leaves"},{"x":-2,"y":5,"z":0,"id":"overworld:leaves"},{"x":-2,"y":5,"z":2,"id":"overworld:log{left=false,front=false,right=true,down=true,size=2,back=false,up=true}"},{"x":-2,"y":6,"z":-3,"id":"overworld:leaves"},{"x":-2,"y":6,"z":-2,"id":"overworld:leaves"},{"x":-2,"y":6,"z":-1,"id":"overworld:leaves"},{"x":-2,"y":6,"z":0,"id":"overworld:leaves"},{"x":-2,"y":6,"z":1,"id":"overworld:leaves"},{"x":-2,"y":6,"z":2,"id":"overworld:leaves"},{"x":-2,"y":6,"z":3,"id":"overworld:leaves"},{"x":-2,"y":7,"z":-1,"id":"overworld:leaves"},{"x":-2,"y":7,"z":0,"id":"overworld:leaves"},{"x":-2,"y":7,"z":1,"id":"overworld:leaves"},{"x":-1,"y":2,"z":0,"id":"overworld:log{left=false,front=false,right=true,down=false,size=4,back=false,up=true}"},{"x":-1,"y":3,"z":-2,"id":"overworld:log{left=false,front=false,right=false,down=false,size=3,back=true,up=true}"},{"x":-1,"y":3,"z":-1,"id":"overworld:log{left=false,front=true,right=false,down=false,size=3,back=true,up=false}"},{"x":-1,"y":3,"z":0,"id":"overworld:log{left=true,front=true,right=false,down=true,size=4,back=true,up=false}"},{"x":-1,"y":3,"z":1,"id":"overworld:log{left=false,front=true,right=false,down=false,size=3,back=false,up=true}"},{"x":-1,"y":4,"z":-2,"id":"overworld:log{left=false,front=false,right=false,down=true,size=2,back=false,up=true}"},{"x":-1,"y":4,"z":1,"id":"overworld:log{left=false,front=false,right=true,down=true,size=2,back=true,up=true}"},{"x":-1,"y":4,"z":2,"id":"overworld:log{left=true,front=true,right=false,down=false,size=2,back=false,up=true}"},{"x":-1,"y":5,"z":-2,"id":"overworld:log{left=true,front=false,right=true,down=true,size=2,back=true,up=true}"},{"x":-1,"y":5,"z":-1,"id":"overworld:leaves"},{"x":-1,"y":5,"z":0,"id":"overworld:leaves"},{"x":-1,"y":5,"z":1,"id":"overworld:leaves"},{"x":-1,"y":5,"z":2,"id":"overworld:leaves"},{"x":-1,"y":6,"z":-4,"id":"overworld:leaves"},{"x":-1,"y":6,"z":-3,"id":"overworld:leaves"},{"x":-1,"y":6,"z":-2,"id":"overworld:leaves"},{"x":-1,"y":6,"z":-1,"id":"overworld:leaves"},{"x":-1,"y":6,"z":0,"id":"overworld:leaves"},{"x":-1,"y":6,"z":1,"id":"overworld:leaves"},{"x":-1,"y":6,"z":2,"id":"overworld:leaves"},{"x":-1,"y":6,"z":3,"id":"overworld:leaves"},{"x":-1,"y":6,"z":4,"id":"overworld:leaves"},{"x":-1,"y":7,"z":-2,"id":"overworld:leaves"},{"x":-1,"y":7,"z":-1,"id":"overworld:leaves"},{"x":-1,"y":7,"z":0,"id":"overworld:leaves"},{"x":-1,"y":7,"z":1,"id":"overworld:leaves"},{"x":-1,"y":7,"z":2,"id":"overworld:leaves"},{"x":-1,"y":8,"z":0,"id":"overworld:leaves"},{"x":0,"y":0,"z":0,"id":"overworld:log{left=false,front=false,right=false,down=false,size=8,back=false,up=true}"},{"x":0,"y":1,"z":0,"id":"overworld:log{left=false,front=false,right=true,down=true,size=7,back=false,up=true}"},{"x":0,"y":2,"z":0,"id":"overworld:log{left=true,front=false,right=false,down=true,size=5,back=false,up=false}"},{"x":0,"y":4,"z":1,"id":"overworld:log{left=true,front=false,right=false,down=false,size=2,back=false,up=true}"},{"x":0,"y":5,"z":-2,"id":"overworld:leaves"},{"x":0,"y":5,"z":-1,"id":"overworld:leaves"},{"x":0,"y":5,"z":0,"id":"overworld:leaves"},{"x":0,"y":5,"z":1,"id":"overworld:log{left=true,front=true,right=true,down=true,size=2,back=true,up=true}"},{"x":0,"y":5,"z":2,"id":"overworld:leaves"},{"x":0,"y":6,"z":-4,"id":"overworld:leaves"},{"x":0,"y":6,"z":-3,"id":"overworld:leaves"},{"x":0,"y":6,"z":-2,"id":"overworld:leaves"},{"x":0,"y":6,"z":-1,"id":"overworld:leaves"},{"x":0,"y":6,"z":0,"id":"overworld:leaves"},{"x":0,"y":6,"z":1,"id":"overworld:leaves"},{"x":0,"y":6,"z":2,"id":"overworld:leaves"},{"x":0,"y":6,"z":3,"id":"overworld:leaves"},{"x":0,"y":6,"z":4,"id":"overworld:leaves"},{"x":0,"y":7,"z":-2,"id":"overworld:leaves"},{"x":0,"y":7,"z":-1,"id":"overworld:leaves"},{"x":0,"y":7,"z":0,"id":"overworld:leaves"},{"x":0,"y":7,"z":1,"id":"overworld:leaves"},{"x":0,"y":7,"z":2,"id":"overworld:leaves"},{"x":0,"y":8,"z":-1,"id":"overworld:leaves"},{"x":0,"y":8,"z":0,"id":"overworld:leaves"},{"x":0,"y":8,"z":1,"id":"overworld:leaves"},{"x":1,"y":1,"z":0,"id":"overworld:log{left=true,front=false,right=true,down=false,size=6,back=false,up=false}"},{"x":1,"y":4,"z":-2,"id":"overworld:log{left=false,front=false,right=true,down=false,size=2,back=false,up=true}"},{"x":1,"y":5,"z":-3,"id":"overworld:leaves"},{"x":1,"y":5,"z":-2,"id":"overworld:log{left=true,front=true,right=true,down=true,size=2,back=true,up=true}"},{"x":1,"y":5,"z":-1,"id":"overworld:leaves"},{"x":1,"y":5,"z":0,"id":"overworld:leaves"},{"x":1,"y":5,"z":1,"id":"overworld:leaves"},{"x":1,"y":5,"z":2,"id":"overworld:leaves"},{"x":1,"y":6,"z":-4,"id":"overworld:leaves"},{"x":1,"y":6,"z":-3,"id":"overworld:leaves"},{"x":1,"y":6,"z":-2,"id":"overworld:leaves"},{"x":1,"y":6,"z":-1,"id":"overworld:leaves"},{"x":1,"y":6,"z":0,"id":"overworld:leaves"},{"x":1,"y":6,"z":1,"id":"overworld:leaves"},{"x":1,"y":6,"z":2,"id":"overworld:leaves"},{"x":1,"y":6,"z":3,"id":"overworld:leaves"},{"x":1,"y":6,"z":4,"id":"overworld:leaves"},{"x":1,"y":7,"z":-2,"id":"overworld:leaves"},{"x":1,"y":7,"z":-1,"id":"overworld:leaves"},{"x":1,"y":7,"z":0,"id":"overworld:leaves"},{"x":1,"y":7,"z":1,"id":"overworld:leaves"},{"x":1,"y":7,"z":2,"id":"overworld:leaves"},{"x":1,"y":8,"z":0,"id":"overworld:leaves"},{"x":2,"y":1,"z":0,"id":"overworld:log{left=true,front=false,right=false,down=false,size=5,back=false,up=true}"},{"x":2,"y":2,"z":0,"id":"overworld:log{left=false,front=false,right=false,down=true,size=4,back=false,up=true}"},{"x":2,"y":3,"z":-2,"id":"overworld:log{left=false,front=false,right=false,down=false,size=3,back=true,up=true}"},{"x":2,"y":3,"z":-1,"id":"overworld:log{left=false,front=true,right=false,down=false,size=3,back=true,up=false}"},{"x":2,"y":3,"z":0,"id":"overworld:log{left=false,front=true,right=true,down=true,size=4,back=false,up=false}"},{"x":2,"y":4,"z":-2,"id":"overworld:log{left=true,front=false,right=false,down=true,size=2,back=false,up=true}"},{"x":2,"y":5,"z":-2,"id":"overworld:leaves"},{"x":2,"y":5,"z":-1,"id":"overworld:leaves"},{"x":2,"y":5,"z":0,"id":"overworld:leaves"},{"x":2,"y":5,"z":1,"id":"overworld:leaves"},{"x":2,"y":6,"z":-3,"id":"overworld:leaves"},{"x":2,"y":6,"z":-2,"id":"overworld:leaves"},{"x":2,"y":6,"z":-1,"id":"overworld:leaves"},{"x":2,"y":6,"z":0,"id":"overworld:leaves"},{"x":2,"y":6,"z":1,"id":"overworld:leaves"},{"x":2,"y":6,"z":2,"id":"overworld:leaves"},{"x":2,"y":6,"z":3,"id":"overworld:leaves"},{"x":2,"y":7,"z":-1,"id":"overworld:leaves"},{"x":2,"y":7,"z":0,"id":"overworld:leaves"},{"x":2,"y":7,"z":1,"id":"overworld:leaves"},{"x":3,"y":3,"z":0,"id":"overworld:log{left=true,front=false,right=false,down=false,size=3,back=false,up=true}"},{"x":3,"y":4,"z":0,"id":"overworld:log{left=false,front=false,right=false,down=true,size=3,back=true,up=true}"},{"x":3,"y":4,"z":1,"id":"overworld:log{left=false,front=true,right=false,down=false,size=2,back=true,up=true}"},{"x":3,"y":4,"z":2,"id":"overworld:log{left=false,front=true,right=false,down=false,size=2,back=false,up=true}"},{"x":3,"y":5,"z":0,"id":"overworld:log{left=true,front=false,right=false,down=true,size=2,back=true,up=true}"},{"x":3,"y":5,"z":1,"id":"overworld:leaves"},{"x":3,"y":5,"z":2,"id":"overworld:log{left=false,front=true,right=false,down=true,size=2,back=false,up=true}"},{"x":3,"y":6,"z":-2,"id":"overworld:leaves"},{"x":3,"y":6,"z":-1,"id":"overworld:leaves"},{"x":3,"y":6,"z":0,"id":"overworld:leaves"},{"x":3,"y":6,"z":1,"id":"overworld:leaves"},{"x":3,"y":6,"z":2,"id":"overworld:leaves"},{"x":4,"y":6,"z":-1,"id":"overworld:leaves"},{"x":4,"y":6,"z":0,"id":"overworld:leaves"},{"x":4,"y":6,"z":1,"id":"overworld:leaves"}]}