{"blocks":[{"x":-4,"y":4,"z":-1,"id":"overworld:leaves"},{"x":-4,"y":4,"z":0,"id":"overworld:leaves"},{"x":-4,"y":4,"z":1,"id":"overworld:leaves"},{"x":-4,"y":5,"z":-1,"id":"overworld:leaves"},{"x":-4,"y":6,"z":-1,"id":"overworld:leaves"},{"x":-3,"y":4,"z":-2,"id":"overworld:leaves"},{"x":-3,"y":4,"z":-1,"id":"overworld:log{down=false,size=2,back=true,right=true,left=true,up=true,front=true}"},{"x":-3,"y":4,"z":0,"id":"overworld:log{down=false,size=2,back=true,right=true,left=true,up=true,front=true}"},{"x":-3,"y":4,"z":1,"id":"overworld:leaves"},{"x":-3,"y":4,"z":2,"id":"overworld:leaves"},{"x":-3,"y":5,"z":-2,"id":"overworld:leaves"},{"x":-3,"y":5,"z":-1,"id":"overworld:log{down=true,size=2,back=true,right=true,left=true,up=true,front=true}"},{"x":-3,"y":5,"z":0,"id":"overworld:leaves"},{"x":-3,"y":5,"z":1,"id":"overworld:leaves"},{"x":-3,"y":5,"z":2,"id":"overworld:leaves"},{"x":-3,"y":6,"z":-2,"id":"overworld:leaves"},{"x":-3,"y":6,"z":-1,"id":"overworld:log{down=true,size=1,back=true,right=true,left=true,up=true,front=true}"},{"x":-3,"y":6,"z":0,"id":"overworld:leaves"},{"x":-3,"y":7,"z":-1,"id":"overworld:leaves"},{"x":-2,"y":2,"z":0,"id":"overworld:log{down=false,size=5,back=false,right=true,left=false,up=true,front=false}"},{"x":-2,"y":3,"z":0,"id":"overworld:log{down=true,size=4,back=false,right=false,left=false,up=true,front=false}"},{"x":-2,"y":4,"z":-3,"id":"overworld:leaves"},{"x":-2,"y":4,"z":-2,"id":"overworld:leaves"},{"x":-2,"y":4,"z":-1,"id":"overworld:leaves"},{"x":-2,"y":4,"z":0,"id":"overworld:log{down=true,size=3,back=true,right=true,left=true,up=true,front=true}"},{"x":-2,"y":4,"z":1,"id":"overworld:log{down=false,size=2,back=true,right=true,left=true,up=true,front=true}"},{"x":-2,"y":4,"z":2,"id":"overworld:leaves"},{"x":-2,"y":4,"z":3,"id":"overworld:leaves"},{"x":-2,"y":5,"z":-3,"id":"overworld:leaves"},{"x":-2,"y":5,"z":-2,"id":"overworld:leaves"},{"x":-2,"y":5,"z":-1,"id":"overworld:leaves"},{"x":-2,"y":5,"z":0,"id":"overworld:leaves"},{"x":-2,"y":5,"z":1,"id":"overworld:log{down=true,size=2,back=true,right=true,left=true,up=true,front=true}"},{"x":-2,"y":5,"z":2,"id":"overworld:log{down=true,size=1,back=true,right=true,left=true,up=true,front=true}"},{"x":-2,"y":5,"z":3,"id":"overworld:leaves"},{"x":-2,"y":6,"z":-2,"id":"overworld:leaves"},{"x":-2,"y":6,"z":-1,"id":"overworld:leaves"},{"x":-2,"y":6,"z":0,"id":"overworld:leaves"},{"x":-2,"y":6,"z":1,"id":"overworld:leaves"},{"x":-2,"y":6,"z":2,"id":"overworld:leaves"},{"x":-2,"y":7,"z":-2,"id":"overworld:leaves"},{"x":-2,"y":7,"z":-1,"id":"overworld:leaves"},{"x":-2,"y":7,"z":0,"id":"overworld:leaves"},{"x":-2,"y":7,"z":1,"id":"overworld:leaves"},{"x":-2,"y":8,"z":0,"id":"overworld:leaves"},{"x":-1,"y":2,"z":0,"id":"overworld:log{down=false,size=6,back=false,right=true,left=true,up=false,front=false}"},{"x":-1,"y":3,"z":2,"id":"overworld:leaves"},{"x":-1,"y":4,"z":-4,"id":"overworld:leaves"},{"x":-1,"y":4,"z":-3,"id":"overworld:leaves"},{"x":-1,"y":4,"z":-2,"id":"overworld:leaves"},{"x":-1,"y":4,"z":-1,"id":"overworld:leaves"},{"x":-1,"y":4,"z":0,"id":"overworld:leaves"},{"x":-1,"y":4,"z":1,"id":"overworld:leaves"},{"x":-1,"y":4,"z":2,"id":"overworld:leaves"},{"x":-1,"y":4,"z":3,"id":"overworld:leaves"},{"x":-1,"y":4,"z":4,"id":"overworld:leaves"},{"x":-1,"y":5,"z":-4,"id":"overworld:leaves"},{"x":-1,"y":5,"z":-3,"id":"overworld:leaves"},{"x":-1,"y":5,"z":-2,"id":"overworld:leaves"},{"x":-1,"y":5,"z":-1,"id":"overworld:leaves"},{"x":-1,"y":5,"z":0,"id":"overworld:leaves"},{"x":-1,"y":5,"z":1,"id":"overworld:leaves"},{"x":-1,"y":5,"z":2,"id":"overworld:leaves"},{"x":-1,"y":5,"z":3,"id":"overworld:leaves"},{"x":-1,"y":5,"z":4,"id":"overworld:leaves"},{"x":-1,"y":6,"z":-3,"id":"overworld:leaves"},{"x":-1,"y":6,"z":-2,"id":"overworld:leaves"},{"x":-1,"y":6,"z":-1,"id":"overworld:leaves"},{"x":-1,"y":6,"z":0,"id":"overworld:leaves"},{"x":-1,"y":6,"z":1,"id":"overworld:leaves"},{"x":-1,"y":6,"z":2,"id":"overworld:leaves"},{"x":-1,"y":6,"z":3,"id":"overworld:leaves"},{"x":-1,"y":7,"z":-2,"id":"overworld:leaves"},{"x":-1,"y":7,"z":-1,"id":"overworld:leaves"},{"x":-1,"y":7,"z":0,"id":"overworld:log{down=true,size=1,back=true,right=true,left=true,up=true,front=true}"},{"x":-1,"y":7,"z":1,"id":"overworld:leaves"},{"x":-1,"y":7,"z":2,"id":"overworld:leaves"},{"x":-1,"y":8,"z":-1,"id":"overworld:leaves"},{"x":-1,"y":8,"z":0,"id":"overworld:leaves"},{"x":-1,"y":8,"z":1,"id":"overworld:leaves"},{"x":0,"y":0,"z":0,"id":"overworld:log{down=false,size=8,back=false,right=false,left=false,up=true,front=false}"},{"x":0,"y":1,"z":0,"id":"overworld:log{down=true,size=7,back=false,right=false,left=false,up=true,front=false}"},{"x":0,"y":2,"z":-1,"id":"overworld:log{down=false,size=5,back=true,right=false,left=false,up=true,front=false}"},{"x":0,"y":2,"z":0,"id":"overworld:log{down=true,size=7,back=true,right=true,left=true,up=false,front=true}"},{"x":0,"y":2,"z":1,"id":"overworld:log{down=false,size=6,back=false,right=false,left=false,up=true,front=true}"},{"x":0,"y":3,"z":-1,"id":"overworld:log{down=true,size=5,back=false,right=false,left=false,up=true,front=false}"},{"x":0,"y":3,"z":1,"id":"overworld:log{down=true,size=5,back=true,right=false,left=false,up=true,front=false}"},{"x":0,"y":3,"z":2,"id":"overworld:log{down=false,size=5,back=false,right=false,left=true,up=true,front=true}"},{"x":0,"y":4,"z":-4,"id":"overworld:leaves"},{"x":0,"y":4,"z":-3,"id":"overworld:log{down=false,size=2,back=true,right=true,left=true,up=true,front=true}"},{"x":0,"y":4,"z":-2,"id":"overworld:log{down=false,size=3,back=true,right=true,left=true,up=true,front=true}"},{"x":0,"y":4,"z":-1,"id":"overworld:log{down=true,size=4,back=true,right=true,left=true,up=true,front=true}"},{"x":0,"y":4,"z":0,"id":"overworld:leaves"},{"x":0,"y":4,"z":1,"id":"overworld:leaves"},{"x":0,"y":4,"z":2,"id":"overworld:log{down=true,size=4,back=true,right=true,left=true,up=true,front=true}"},{"x":0,"y":4,"z":3,"id":"overworld:log{down=false,size=4,back=true,right=true,left=true,up=true,front=true}"},{"x":0,"y":4,"z":4,"id":"overworld:leaves"},{"x":0,"y":5,"z":-4,"id":"overworld:leaves"},{"x":0,"y":5,"z":-3,"id":"overworld:log{down=true,size=2,back=true,right=true,left=true,up=true,front=true}"},{"x":0,"y":5,"z":-2,"id":"overworld:leaves"},{"x":0,"y":5,"z":-1,"id":"overworld:log{down=true,size=6,back=true,right=true,left=true,up=true,front=true}"},{"x":0,"y":5,"z":0,"id":"overworld:log{down=true,size=5,back=true,right=true,left=true,up=true,front=true}"},{"x":0,"y":5,"z":1,"id":"overworld:leaves"},{"x":0,"y":5,"z":2,"id":"overworld:leaves"},{"x":0,"y":5,"z":3,"id":"overworld:log{down=true,size=3,back=true,right=true,left=true,up=true,front=true}"},{"x":0,"y":5,"z":4,"id":"overworld:log{down=true,size=1,back=true,right=true,left=true,up=true,front=true}"},{"x":0,"y":5,"z":5,"id":"overworld:leaves"},{"x":0,"y":6,"z":-4,"id":"overworld:leaves"},{"x":0,"y":6,"z":-3,"id":"overworld:log{down=true,size=1,back=true,right=true,left=true,up=true,front=true}"},{"x":0,"y":6,"z":-2,"id":"overworld:leaves"},{"x":0,"y":6,"z":-1,"id":"overworld:leaves"},{"x":0,"y":6,"z":0,"id":"overworld:log{down=true,size=4,back=true,right=true,left=true,up=true,front=true}"},{"x":0,"y":6,"z":1,"id":"overworld:leaves"},{"x":0,"y":6,"z":2,"id":"overworld:leaves"},{"x":0,"y":6,"z":3,"id":"overworld:leaves"},{"x":0,"y":6,"z":4,"id":"overworld:leaves"},{"x":0,"y":7,"z":-3,"id":"overworld:leaves"},{"x":0,"y":7,"z":-2,"id":"overworld:leaves"},{"x":0,"y":7,"z":-1,"id":"overworld:log{down=true,size=1,back=true,right=true,left=true,up=true,front=true}"},{"x":0,"y":7,"z":0,"id":"overworld:log{down=true,size=4,back=true,right=true,left=true,up=true,front=true}"},{"x":0,"y":7,"z":1,"id":"overworld:log{down=true,size=1,back=true,right=true,left=true,up=true,front=true}"},{"x":0,"y":7,"z":2,"id":"overworld:leaves"},{"x":0,"y":8,"z":-2,"id":"overworld:leaves"},{"x":0,"y":8,"z":-1,"id":"overworld:leaves"},{"x":0,"y":8,"z":0,"id":"overworld:leaves"},{"x":0,"y":8,"z":1,"id":"overworld:leaves"},{"x":0,"y":9,"z":0,"id":"overworld:leaves"},{"x":1,"y":2,"z":0,"id":"overworld:log{down=false,size=7,back=false,right=true,left=true,up=false,front=false}"},{"x":1,"y":4,"z":-3,"id":"overworld:leaves"},{"x":1,"y":4,"z":-2,"id":"overworld:leaves"},{"x":1,"y":4,"z":-1,"id":"overworld:leaves"},{"x":1,"y":4,"z":0,"id":"overworld:leaves"},{"x":1,"y":4,"z":2,"id":"overworld:log{down=false,size=4,back=true,right=true,left=true,up=true,front=false}"},{"x":1,"y":4,"z":3,"id":"overworld:leaves"},{"x":1,"y":4,"z":4,"id":"overworld:leaves"},{"x":1,"y":5,"z":-4,"id":"overworld:leaves"},{"x":1,"y":5,"z":-3,"id":"overworld:leaves"},{"x":1,"y":5,"z":-2,"id":"overworld:leaves"},{"x":1,"y":5,"z":-1,"id":"overworld:leaves"},{"x":1,"y":5,"z":0,"id":"overworld:leaves"},{"x":1,"y":5,"z":1,"id":"overworld:leaves"},{"x":1,"y":5,"z":2,"id":"overworld:log{down=true,size=3,back=true,right=true,left=true,up=true,front=true}"},{"x":1,"y":5,"z":3,"id":"overworld:leaves"},{"x":1,"y":5,"z":4,"id":"overworld:leaves"},{"x":1,"y":6,"z":-4,"id":"overworld:leaves"},{"x":1,"y":6,"z":-3,"id":"overworld:leaves"},{"x":1,"y":6,"z":-2,"id":"overworld:leaves"},{"x":1,"y":6,"z":-1,"id":"overworld:leaves"},{"x":1,"y":6,"z":0,"id":"overworld:leaves"},{"x":1,"y":6,"z":1,"id":"overworld:leaves"},{"x":1,"y":6,"z":2,"id":"overworld:log{down=true,size=1,back=true,right=true,left=true,up=true,front=true}"},{"x":1,"y":6,"z":3,"id":"overworld:leaves"},{"x":1,"y":6,"z":4,"id":"overworld:leaves"},{"x":1,"y":7,"z":-2,"id":"overworld:leaves"},{"x":1,"y":7,"z":-1,"id":"overworld:leaves"},{"x":1,"y":7,"z":0,"id":"overworld:log{down=true,size=1,back=true,right=true,left=true,up=true,front=true}"},{"x":1,"y":7,"z":1,"id":"overworld:leaves"},{"x":1,"y":7,"z":2,"id":"overworld:leaves"},{"x":1,"y":8,"z":-1,"id":"overworld:leaves"},{"x":1,"y":8,"z":0,"id":"overworld:leaves"},{"x":1,"y":8,"z":1,"id":"overworld:leaves"},{"x":2,"y":2,"z":0,"id":"overworld:log{down=false,size=6,back=false,right=false,left=true,up=true,front=false}"},{"x":2,"y":3,"z":-2,"id":"overworld:leaves"},{"x":2,"y":3,"z":-1,"id":"overworld:log{down=false,size=4,back=true,right=false,left=false,up=true,front=true}"},{"x":2,"y":3,"z":0,"id":"overworld:log{down=true,size=5,back=true,right=true,left=false,up=false,front=true}"},{"x":2,"y":3,"z":1,"id":"overworld:leaves"},{"x":2,"y":4,"z":-3,"id":"overworld:leaves"},{"x":2,"y":4,"z":-2,"id":"overworld:leaves"},{"x":2,"y":4,"z":-1,"id":"overworld:log{down=true,size=3,back=false,right=true,left=true,up=true,front=true}"},{"x":2,"y":4,"z":1,"id":"overworld:leaves"},{"x":2,"y":4,"z":2,"id":"overworld:leaves"},{"x":2,"y":4,"z":3,"id":"overworld:leaves"},{"x":2,"y":5,"z":-3,"id":"overworld:leaves"},{"x":2,"y":5,"z":-2,"id":"overworld:log{down=true,size=1,back=true,right=true,left=true,up=true,front=true}"},{"x":2,"y":5,"z":-1,"id":"overworld:log{down=true,size=2,back=true,right=true,left=true,up=true,front=true}"},{"x":2,"y":5,"z":0,"id":"overworld:leaves"},{"x":2,"y":5,"z":1,"id":"overworld:leaves"},{"x":2,"y":5,"z":2,"id":"overworld:leaves"},{"x":2,"y":5,"z":3,"id":"overworld:leaves"},{"x":2,"y":5,"z":4,"id":"overworld:leaves"},{"x":2,"y":6,"z":-3,"id":"overworld:leaves"},{"x":2,"y":6,"z":-2,"id":"overworld:leaves"},{"x":2,"y":6,"z":-1,"id":"overworld:leaves"},{"x":2,"y":6,"z":0,"id":"overworld:leaves"},{"x":2,"y":6,"z":1,"id":"overworld:leaves"},{"x":2,"y":6,"z":2,"id":"overworld:leaves"},{"x":2,"y":6,"z":3,"id":"overworld:leaves"},{"x":2,"y":7,"z":-2,"id":"overworld:leaves"},{"x":2,"y":7,"z":-1,"id":"overworld:leaves"},{"x":2,"y":7,"z":0,"id":"overworld:leaves"},{"x":2,"y":7,"z":1,"id":"overworld:leaves"},{"x":2,"y":7,"z":2,"id":"overworld:leaves"},{"x":2,"y":8,"z":0,"id":"overworld:leaves"},{"x":3,"y":3,"z":0,"id":"overworld:log{down=false,size=4,back=false,right=false,left=true,up=true,front=false}"},{"x":3,"y":4,"z":-2,"id":"overworld:leaves"},{"x":3,"y":4,"z":-1,"id":"overworld:leaves"},{"x":3,"y":4,"z":0,"id":"overworld:log{down=true,size=4,back=true,right=true,left=false,up=true,front=true}"},{"x":3,"y":4,"z":1,"id":"overworld:log{down=false,size=4,back=true,right=true,left=true,up=true,front=true}"},{"x":3,"y":4,"z":2,"id":"overworld:leaves"},{"x":3,"y":5,"z":-3,"id":"overworld:leaves"},{"x":3,"y":5,"z":-2,"id":"overworld:leaves"},{"x":3,"y":5,"z":-1,"id":"overworld:leaves"},{"x":3,"y":5,"z":0,"id":"overworld:leaves"},{"x":3,"y":5,"z":1,"id":"overworld:log{down=true,size=2,back=true,right=true,left=true,up=true,front=true}"},{"x":3,"y":5,"z":2,"id":"overworld:log{down=true,size=1,back=true,right=true,left=true,up=true,front=true}"},{"x":3,"y":5,"z":3,"id":"overworld:leaves"},{"x":3,"y":6,"z":-2,"id":"overworld:leaves"},{"x":3,"y":6,"z":-1,"id":"overworld:leaves"},{"x":3,"y":6,"z":0,"id":"overworld:leaves"},{"x":3,"y":6,"z":1,"id":"overworld:leaves"},{"x":3,"y":6,"z":2,"id":"overworld:leaves"},{"x":3,"y":7,"z":0,"id":"overworld:leaves"},{"x":3,"y":7,"z":1,"id":"overworld:leaves"},{"x":4,"y":4,"z":-1,"id":"overworld:leaves"},{"x":4,"y":4,"z":0,"id":"overworld:leaves"},{"x":4,"y":4,"z":1,"id":"overworld:leaves"},{"x":4,"y":5,"z":-1,"id":"overworld:leaves"},{"x":4,"y":5,"z":0,"id":"overworld:leaves"},{"x":4,"y":5,"z":1,"id":"overworld:leaves"},{"x":4,"y":5,"z":2,"id":"overworld:leaves"},{"x":4,"y":6,"z":1,"id":"overworld:leaves"}]}